Workbook

Sheet Players
A1: Player | B1: Control & Receiving | C1: Passing & Distribution | D1: Dribbling & Manipulation | E1: Striking & Finishing | F1: Defending & Tackling | G1: Game Intelligence | H1: Speed & Acceleration | I1: Physical Literacy | J1: Mental & Psycho-Social | K1: Score | L1: Score + 10% | M1: Overall
A2: Alan | B2: Elite | C2: Elite | D2: Advanced | E2: Advanced | F2: Advanced | G2: Elite | H2: Advanced | I2: Advanced | J2: Advanced | K2: =PlayerAttributes!AK3 -> 60.1 | L2: =K2*1.1 -> 66.11 | M2: {=XLOOKUP((K2 * 1.1), Scoring!$B$2:$B$5, Scoring!$A$2:$A$5, "Needs Improvement", -1)} -> Advanced
A3: Leon | B3: Elite | C3: Elite | D3: Elite | E3: Elite | F3: Intermediate | G3: Advanced | H3: Advanced | I3: Advanced | J3: Development | K3: =PlayerAttributes!AK4 -> 52.82 | L3: =K3*1.1 -> 58.102 | M3: {=XLOOKUP((K3 * 1.1), Scoring!$B$2:$B$5, Scoring!$A$2:$A$5, "Needs Improvement", -1)} -> Advanced
A4: Jonny | B4: Advanced | C4: Advanced | D4: Advanced | E4: Advanced | F4: Advanced | G4: Intermediate | H4: Elite | I4: Advanced | J4: Advanced | K4: =PlayerAttributes!AK5 -> 49.19 | L4: =K4*1.1 -> 54.109 | M4: {=XLOOKUP((K4 * 1.1), Scoring!$B$2:$B$5, Scoring!$A$2:$A$5, "Needs Improvement", -1)} -> Advanced
A5: Cooper | B5: Intermediate | C5: Advanced | D5: Advanced | E5: Intermediate | F5: Elite | G5: Advanced | H5: Advanced | I5: Elite | J5: Intermediate | K5: =PlayerAttributes!AK6 -> 53.46 | L5: =K5*1.1 -> 58.806 | M5: {=XLOOKUP((K5 * 1.1), Scoring!$B$2:$B$5, Scoring!$A$2:$A$5, "Needs Improvement", -1)} -> Advanced
A6: Michael | B6: Advanced | C6: Advanced | D6: Advanced | E6: Advanced | F6: Advanced | G6: Intermediate | H6: Advanced | I6: Advanced | J6: Intermediate | K6: =PlayerAttributes!AK7 -> 46.22 | L6: =K6*1.1 -> 50.842 | M6: {=XLOOKUP((K6 * 1.1), Scoring!$B$2:$B$5, Scoring!$A$2:$A$5, "Needs Improvement", -1)} -> Intermediate
A7: Bryan | B7: Advanced | C7: Advanced | D7: Advanced | E7: Intermediate | F7: Advanced | G7: Advanced | H7: Advanced | I7: Advanced | J7: Intermediate | K7: =PlayerAttributes!AK8 -> 49.96 | L7: =K7*1.1 -> 54.956 | M7: {=XLOOKUP((K7 * 1.1), Scoring!$B$2:$B$5, Scoring!$A$2:$A$5, "Needs Improvement", -1)} -> Advanced
A8: Cairan | B8: Advanced | C8: Advanced | D8: Advanced | E8: Advanced | F8: Advanced | G8: Advanced | H8: Advanced | I8: Elite | J8: Intermediate | K8: =PlayerAttributes!AK9 -> 53.53 | L8: =K8*1.1 -> 58.883 | M8: {=XLOOKUP((K8 * 1.1), Scoring!$B$2:$B$5, Scoring!$A$2:$A$5, "Needs Improvement", -1)} -> Advanced
A9: James | B9: Advanced | C9: Advanced | D9: Intermediate | E9: Intermediate | F9: Advanced | G9: Advanced | H9: Development | I9: Intermediate | J9: Intermediate | K9: =PlayerAttributes!AK10 -> 42.99 | L9: =K9*1.1 -> 47.289 | M9: {=XLOOKUP((K9 * 1.1), Scoring!$B$2:$B$5, Scoring!$A$2:$A$5, "Needs Improvement", -1)} -> Intermediate
A10: Jayden | B10: Advanced | C10: Advanced | D10: Advanced | E10: Intermediate | F10: Advanced | G10: Intermediate | H10: Advanced | I10: Advanced | J10: Intermediate | K10: =PlayerAttributes!AK11 -> 45.71 | L10: =K10*1.1 -> 50.281 | M10: {=XLOOKUP((K10 * 1.1), Scoring!$B$2:$B$5, Scoring!$A$2:$A$5, "Needs Improvement", -1)} -> Intermediate
A11: Fin | B11: Advanced | C11: Intermediate | D11: Intermediate | E11: Intermediate | F11: Intermediate | G11: Advanced | H11: Advanced | I11: Intermediate | J11: Intermediate | K11: =PlayerAttributes!AK12 -> 41.97 | L11: =K11*1.1 -> 46.167 | M11: {=XLOOKUP((K11 * 1.1), Scoring!$B$2:$B$5, Scoring!$A$2:$A$5, "Needs Improvement", -1)} -> Intermediate
A12: Laszlo | B12: Intermediate | C12: Intermediate | D12: Intermediate | E12: Intermediate | F12: Intermediate | G12: Intermediate | H12: Advanced | I12: Advanced | J12: Intermediate | K12: =PlayerAttributes!AK13 -> 39.25 | L12: =K12*1.1 -> 43.175 | M12: {=XLOOKUP((K12 * 1.1), Scoring!$B$2:$B$5, Scoring!$A$2:$A$5, "Needs Improvement", -1)} -> Intermediate
A13: Mark F (GK) | B13: Development | C13: Development | D13: Development | E13: Development | F13: Development | G13: Development | H13: Development | I13: Development | J13: Development | K13: =PlayerAttributes!AK14 -> 18 | L13: =K13*1.1 -> 19.8 | M13: {=XLOOKUP((K13 * 1.1), Scoring!$B$2:$B$5, Scoring!$A$2:$A$5, "Needs Improvement", -1)} -> Development
... A19: Cayden | B19: Intermediate | C19: Intermediate | D19: Intermediate | E19: Intermediate | F19: Intermediate | G19: Intermediate | H19: Intermediate | I19: Intermediate | J19: Intermediate | K19: =PlayerAttributes!AK20 -> 35 | L19: =K19*1.1 -> 38.5 | M19: {=XLOOKUP((K19 * 1.1), Scoring!$B$2:$B$5, Scoring!$A$2:$A$5, "Needs Improvement", -1)} -> Intermediate
A21: Game Type: | B21: 11s
A23: Competency | B23: Development | D23: Intermediate | F23: Advanced | I23: Elite
A24: Control & Receiving | B24: Controls a rolling ball with dominant foot without losing balance. | D24: Controls rolling/bouncing ball with either foot under passive pressure. | F24: Controls aerial/driven balls using multiple surfaces under active pressure. | I24: Instantly kills high-velocity balls with any body part under extreme pressure.
A25: Passing & Distribution | B25: Passes accurately over short distances with inside of dominant foot. | D25: Completes short passes with both feet and also lofted passes with dominant foot. | F25: Consistently hits varied passes with dominant foot to moving targets and short passes with none dominant foot. | I25: Breaks defensive lines with single-touch passing and pinpoint long-range distribution.
A26: Dribbling & Manipulation | B26: Keeps the ball within playing distance at a jogging pace. | D26: Changes direction/speed to bypass a static defender using basic skill moves. | F26: Close control at high speeds utilizing dynamic feints to beat active defenders 1v1. | I26: Flawless manipulation at maximum sprint speed using micro-touches in tight spaces.
A27: Striking & Finishing | B27: Strikes a stationary ball cleanly with the laces. | D27: Strikes a moving ball accurately toward the goal with the dominant foot. | F27: Consistently strikes with power and accuracy from various angles/distances using dominant foot and can shoot with weaker foot. | I27: Clinical finishing with minimal backlift and exploits minute gaps from distance under duress.
A28: Defending & Tackling | B28: Understands goal-side positioning and tries to recover the ball. | D28: Executes clean standing and sliding tackles and understands body positioning. | F28: Can tackle at speed and understands slowing opponent attacks down. | I28: Consitently organises and correct prioritises defensive responsibilities and structure press and defensive balance.
A29: Game Intelligence | B29: Understands pitch boundaries and the direction of play. | D29: Scans occasionally before receiving and recognizes basic team shape. | F29: Consistently scans anticipates play to intercept and creates space off the ball. | I29: Operates two steps ahead of play exploits blind spots continuously and dictates match tempo.
A30: Speed & Acceleration | B30: Demonstrates basic running mechanics with functional linear sprint speed, but lacks a quick burst off the mark. | D30: Shows noticeable acceleration over short distances and can outpace opponents when given a running start. | F30: Displays rapid acceleration from a standing start and maintains high sprint speed over distance to separate from active defenders. | I30: Possesses explosive first-step acceleration and elite maximum sprint speed, allowing for instant separation and rapid closing speed.
A31: Physical Literacy | B31: Fundamental coordination and agility without losing balance during basic movements. | D31: Shields the ball using body frame and sustains energy through majority of training and game time | F31: Exhibits strong core stability, contests aerial duels safely, and maintains high-intensity execution late in games. | I31: Professional-academy biomechanics, elite functional strength for physical duels, and rapid recovery throughout the entire game.
A32: Mental & Psycho-Social | B32: Engages willingly and follows basic coaching instructions | D32: Shows resilience after mistakes and begins verbally interacting with teammates. | F32: Communicates tactical info clearly and remains composed under match pressure. | I32: Absolute psychological resilience drives team standards and exhibits peak composure

Sheet PlayerAttributes
B1: Control & Receiving | C1: Control & Receiving | D1: Control & Receiving | E1: Control & Receiving | F1: Passing & Distribution | G1: Passing & Distribution | H1: Passing & Distribution | I1: Dribbling & Manipulation | J1: Dribbling & Manipulation | K1: Dribbling & Manipulation | L1: Dribbling & Manipulation | M1: Striking & Finishing | N1: Striking & Finishing | O1: Striking & Finishing | P1: Striking & Finishing | Q1: Striking & Finishing | R1: Defending & Tackling | S1: Defending & Tackling | T1: Defending & Tackling | U1: Defending & Tackling | V1: Game Intelligence | W1: Game Intelligence | X1: Game Intelligence | Y1: Game Intelligence | Z1: Game Intelligence | AA1: Game Intelligence | AB1: Speed & Acceleration | AC1: Speed & Acceleration | AD1: Physical Literacy | AE1: Physical Literacy | AF1: Physical Literacy | AG1: Physical Literacy | AH1: Mental & Psycho-Social | AI1: Mental & Psycho-Social | AJ1: Mental & Psycho-Social
A2: Player | B2: Ball Control | C2: Weak Foot | D2: Volleys | E2: Reactions | F2: Short Passing | G2: Long Passing | H2: Crossing | I2: Dribbling | J2: Agility | K2: Balance | L2: Pace | M2: Finishing | N2: Shot Power | O2: Long Shot | P2: Free Kick | Q2: Penalties | R2: Standing Tackle | S2: Sliding Tackle | T2: Marking | U2: Aggression | V2: Awareness | W2: Vision | X2: Positioning | Y2: Interceptions | Z2: Attacking Position | AA2: Defensive Positioning | AB2: Acceleration | AC2: Sprint Speed | AD2: Strength | AE2: Stamina | AF2: Jumping | AG2: Heading | AH2: Communication | AI2: Composure | AJ2: Positivity | AK2: Total
A3: Alan | B3: {=(XLOOKUP(Players!$B2, Scoring!$A:$A, Scoring!$B:$B,"",1)) * (XLOOKUP(B$2, Weightings!$C$2:$C$36, Weightings!$I$2:$I$36,"",1))} -> 2.8 | C3: {=(XLOOKUP(Players!$B2, Scoring!$A:$A, Scoring!$B:$B,"",1)) * (XLOOKUP(C$2, Weightings!$C$2:$C$36, Weightings!$I$2:$I$36,"",1))} -> 1.4 | D3: {=(XLOOKUP(Players!$B2, Scoring!$A:$A, Scoring!$B:$B,"",1)) * (XLOOKUP(D$2, Weightings!$C$2:$C$36, Weightings!$I$2:$I$36,"",1))} -> 0 | E3: {=(XLOOKUP(Players!$B2, Scoring!$A:$A, Scoring!$B:$B,"",1)) * (XLOOKUP(E$2, Weightings!$C$2:$C$36, Weightings!$I$2:$I$36,"",1))} -> 1.4 | F3: {=(XLOOKUP(Players!$C2, Scoring!$A:$A, Scoring!$B:$B,"",1)) * (XLOOKUP(F$2, Weightings!$C$2:$C$36, Weightings!$I$2:$I$36,"",1))} -> 3.5 | G3: {=(XLOOKUP(Players!$C2, Scoring!$A:$A, Scoring!$B:$B,"",1)) * (XLOOKUP(G$2, Weightings!$C$2:$C$36, Weightings!$I$2:$I$36,"",1))} -> 3.5 | H3: {=(XLOOKUP(Players!$C2, Scoring!$A:$A, Scoring!$B:$B,"",1)) * (XLOOKUP(H$2, Weightings!$C$2:$C$36, Weightings!$I$2:$I$36,"",1))} -> 1.4 | I3: {=(XLOOKUP(Players!$D2, Scoring!$A:$A, Scoring!$B:$B,"",1)) * (XLOOKUP(I$2, Weightings!$C$2:$C$36, Weightings!$I$2:$I$36,"",1))} -> 1.04 | J3: {=(XLOOKUP(Players!$D2, Scoring!$A:$A, Scoring!$B:$B,"",1)) * (XLOOKUP(J$2, Weightings!$C$2:$C$36, Weightings!$I$2:$I$36,"",1))} -> 1.04 | K3: {=(XLOOKUP(Players!$D2, Scoring!$A:$A, Scoring!$B:$B,"",1)) * (XLOOKUP(K$2, Weightings!$C$2:$C$36, Weightings!$I$2:$I$36,"",1))} -> 0.52 | L3: {=(XLOOKUP(Players!$D2, Scoring!$A:$A, Scoring!$B:$B,"",1)) * (XLOOKUP(L$2, Weightings!$C$2:$C$36, Weightings!$I$2:$I$36,"",1))} -> 1.56 | M3: {=(XLOOKUP(Players!$E2, Scoring!$A:$A, Scoring!$B:$B,"",1)) * (XLOOKUP(M$2, Weightings!$C$2:$C$36, Weightings!$I$2:$I$36,"",1))} -> 1.56 | N3: {=(XLOOKUP(Players!$E2, Scoring!$A:$A, Scoring!$B:$B,"",1)) * (XLOOKUP(N$2, Weightings!$C$2:$C$36, Weightings!$I$2:$I$36,"",1))} -> 0 | O3: {=(XLOOKUP(Players!$E2, Scoring!$A:$A, Scoring!$B:$B,"",1)) * (XLOOKUP(O$2, Weightings!$C$2:$C$36, Weightings!$I$2:$I$36,"",1))} -> 0 | P3: {=(XLOOKUP(Players!$E2, Scoring!$A:$A, Scoring!$B:$B,"",1)) * (XLOOKUP(P$2, Weightings!$C$2:$C$36, Weightings!$I$2:$I$36,"",1))} -> 0 | Q3: {=(XLOOKUP(Players!$E2, Scoring!$A:$A, Scoring!$B:$B,"",1)) * (XLOOKUP(Q$2, Weightings!$C$2:$C$36, Weightings!$I$2:$I$36,"",1))} -> 0 | R3: {=(XLOOKUP(Players!$F2, Scoring!$A:$A, Scoring!$B:$B,"",1)) * (XLOOKUP(R$2, Weightings!$C$2:$C$36, Weightings!$I$2:$I$36,"",1))} -> 1.56 | S3: {=(XLOOKUP(Players!$F2, Scoring!$A:$A, Scoring!$B:$B,"",1)) * (XLOOKUP(S$2, Weightings!$C$2:$C$36, Weightings!$I$2:$I$36,"",1))} -> 0.52 | T3: {=(XLOOKUP(Players!$F2, Scoring!$A:$A, Scoring!$B:$B,"",1)) * (XLOOKUP(T$2, Weightings!$C$2:$C$36, Weightings!$I$2:$I$36,"",1))} -> 2.08 | U3: {=(XLOOKUP(Players!$F2, Scoring!$A:$A, Scoring!$B:$B,"",1)) * (XLOOKUP(U$2, Weightings!$C$2:$C$36, Weightings!$I$2:$I$36,"",1))} -> 1.04 | V3: {=(XLOOKUP(Players!$G2, Scoring!$A:$A, Scoring!$B:$B,"",1)) * (XLOOKUP(V$2, Weightings!$C$2:$C$36, Weightings!$I$2:$I$36,"",1))} -> 3.5 | W3: {=(XLOOKUP(Players!$G2, Scoring!$A:$A, Scoring!$B:$B,"",1)) * (XLOOKUP(W$2, Weightings!$C$2:$C$36, Weightings!$I$2:$I$36,"",1))} -> 2.1 | X3: {=(XLOOKUP(Players!$G2, Scoring!$A:$A, Scoring!$B:$B,"",1)) * (XLOOKUP(X$2, Weightings!$C$2:$C$36, Weightings!$I$2:$I$36,"",1))} -> 3.5 | Y3: {=(XLOOKUP(Players!$G2, Scoring!$A:$A, Scoring!$B:$B,"",1)) * (XLOOKUP(Y$2, Weightings!$C$2:$C$36, Weightings!$I$2:$I$36,"",1))} -> 2.8 | Z3: {=(XLOOKUP(Players!$G2, Scoring!$A:$A, Scoring!$B:$B,"",1)) * (XLOOKUP(Z$2, Weightings!$C$2:$C$36, Weightings!$I$2:$I$36,"",1))} -> 2.1 | AA3: {=(XLOOKUP(Players!$G2, Scoring!$A:$A, Scoring!$B:$B,"",1)) * (XLOOKUP(AA$2, Weightings!$C$2:$C$36, Weightings!$I$2:$I$36,"",1))} -> 3.5 | AB3: {=(XLOOKUP(Players!$H2, Scoring!$A:$A, Scoring!$B:$B,"",1)) * (XLOOKUP(AB$2, Weightings!$C$2:$C$36, Weightings!$I$2:$I$36,"",1))} -> 1.56 | AC3: {=(XLOOKUP(Players!$H2, Scoring!$A:$A, Scoring!$B:$B,"",1)) * (XLOOKUP(AC$2, Weightings!$C$2:$C$36, Weightings!$I$2:$I$36,"",1))} -> 2.6 | AD3: {=(XLOOKUP(Players!$I2, Scoring!$A:$A, Scoring!$B:$B,"",1)) * (XLOOKUP(AD$2, Weightings!$C$2:$C$36, Weightings!$I$2:$I$36,"",1))} -> 2.08 | AE3: {=(XLOOKUP(Players!$I2, Scoring!$A:$A, Scoring!$B:$B,"",1)) * (XLOOKUP(AE$2, Weightings!$C$2:$C$36, Weightings!$I$2:$I$36,"",1))} -> 3.64 | AF3: {=(XLOOKUP(Players!$I2, Scoring!$A:$A, Scoring!$B:$B,"",1)) * (XLOOKUP(AF$2, Weightings!$C$2:$C$36, Weightings!$I$2:$I$36,"",1))} -> 1.56 | AG3: {=(XLOOKUP(Players!$I2, Scoring!$A:$A, Scoring!$B:$B,"",1)) * (XLOOKUP(AG$2, Weightings!$C$2:$C$36, Weightings!$I$2:$I$36,"",1))} -> 1.56 | AH3: {=(XLOOKUP(Players!$J2, Scoring!$A:$A, Scoring!$B:$B,"",1)) * (XLOOKUP(AH$2, Weightings!$C$2:$C$36, Weightings!$I$2:$I$36,"",1))} -> 2.08 | AI3: {=(XLOOKUP(Players!$J2, Scoring!$A:$A, Scoring!$B:$B,"",1)) * (XLOOKUP(AI$2, Weightings!$C$2:$C$36, Weightings!$I$2:$I$36,"",1))} -> 2.08 | AJ3: {=(XLOOKUP(Players!$J2, Scoring!$A:$A, Scoring!$B:$B,"",1)) * (XLOOKUP(AJ$2, Weightings!$C$2:$C$36, Weightings!$I$2:$I$36,"",1))} -> 0.52 | AK3: =SUM(A3:AJ3) -> 60.1
A4: Leon | B4: {=(XLOOKUP(Players!$B3, Scoring!$A:$A, Scoring!$B:$B,"",1)) * (XLOOKUP(B$2, Weightings!$C$2:$C$36, Weightings!$I$2:$I$36,"",1))} -> 2.8 | C4: {=(XLOOKUP(Players!$B3, Scoring!$A:$A, Scoring!$B:$B,"",1)) * (XLOOKUP(C$2, Weightings!$C$2:$C$36, Weightings!$I$2:$I$36,"",1))} -> 1.4 | D4: {=(XLOOKUP(Players!$B3, Scoring!$A:$A, Scoring!$B:$B,"",1)) * (XLOOKUP(D$2, Weightings!$C$2:$C$36, Weightings!$I$2:$I$36,"",1))} -> 0 | E4: {=(XLOOKUP(Players!$B3, Scoring!$A:$A, Scoring!$B:$B,"",1)) * (XLOOKUP(E$2, Weightings!$C$2:$C$36, Weightings!$I$2:$I$36,"",1))} -> 1.4 | F4: {=(XLOOKUP(Players!$C3, Scoring!$A:$A, Scoring!$B:$B,"",1)) * (XLOOKUP(F$2, Weightings!$C$2:$C$36, Weightings!$I$2:$I$36,"",1))} -> 3.5 | G4: {=(XLOOKUP(Players!$C3, Scoring!$A:$A, Scoring!$B:$B,"",1)) * (XLOOKUP(G$2, Weightings!$C$2:$C$36, Weightings!$I$2:$I$36,"",1))} -> 3.5 | H4: {=(XLOOKUP(Players!$C3, Scoring!$A:$A, Scoring!$B:$B,"",1)) * (XLOOKUP(H$2, Weightings!$C$2:$C$36, Weightings!$I$2:$I$36,"",1))} -> 1.4 | I4: {=(XLOOKUP(Players!$D3, Scoring!$A:$A, Scoring!$B:$B,"",1)) * (XLOOKUP(I$2, Weightings!$C$2:$C$36, Weightings!$I$2:$I$36,"",1))} -> 1.4 | J4: {=(XLOOKUP(Players!$D3, Scoring!$A:$A, Scoring!$B:$B,"",1)) * (XLOOKUP(J$2, Weightings!$C$2:$C$36, Weightings!$I$2:$I$36,"",1))} -> 1.4 | K4: {=(XLOOKUP(Players!$D3, Scoring!$A:$A, Scoring!$B:$B,"",1)) * (XLOOKUP(K$2, Weightings!$C$2:$C$36, Weightings!$I$2:$I$36,"",1))} -> 0.7 | L4: {=(XLOOKUP(Players!$D3, Scoring!$A:$A, Scoring!$B:$B,"",1)) * (XLOOKUP(L$2, Weightings!$C$2:$C$36, Weightings!$I$2:$I$36,"",1))} -> 2.1 | M4: {=(XLOOKUP(Players!$E3, Scoring!$A:$A, Scoring!$B:$B,"",1)) * (XLOOKUP(M$2, Weightings!$C$2:$C$36, Weightings!$I$2:$I$36,"",1))} -> 2.1 | N4: {=(XLOOKUP(Players!$E3, Scoring!$A:$A, Scoring!$B:$B,"",1)) * (XLOOKUP(N$2, Weightings!$C$2:$C$36, Weightings!$I$2:$I$36,"",1))} -> 0 | O4: {=(XLOOKUP(Players!$E3, Scoring!$A:$A, Scoring!$B:$B,"",1)) * (XLOOKUP(O$2, Weightings!$C$2:$C$36, Weightings!$I$2:$I$36,"",1))} -> 0 | P4: {=(XLOOKUP(Players!$E3, Scoring!$A:$A, Scoring!$B:$B,"",1)) * (XLOOKUP(P$2, Weightings!$C$2:$C$36, Weightings!$I$2:$I$36,"",1))} -> 0 | Q4: {=(XLOOKUP(Players!$E3, Scoring!$A:$A, Scoring!$B:$B,"",1)) * (XLOOKUP(Q$2, Weightings!$C$2:$C$36, Weightings!$I$2:$I$36,"",1))} -> 0 | R4: {=(XLOOKUP(Players!$F3, Scoring!$A:$A, Scoring!$B:$B,"",1)) * (XLOOKUP(R$2, Weightings!$C$2:$C$36, Weightings!$I$2:$I$36,"",1))} -> 1.05 | S4: {=(XLOOKUP(Players!$F3, Scoring!$A:$A, Scoring!$B:$B,"",1)) * (XLOOKUP(S$2, Weightings!$C$2:$C$36, Weightings!$I$2:$I$36,"",1))} -> 0.35 | T4: {=(XLOOKUP(Players!$F3, Scoring!$A:$A, Scoring!$B:$B,"",1)) * (XLOOKUP(T$2, Weightings!$C$2:$C$36, Weightings!$I$2:$I$36,"",1))} -> 1.4 | U4: {=(XLOOKUP(Players!$F3, Scoring!$A:$A, Scoring!$B:$B,"",1)) * (XLOOKUP(U$2, Weightings!$C$2:$C$36, Weightings!$I$2:$I$36,"",1))} -> 0.7 | V4: {=(XLOOKUP(Players!$G3, Scoring!$A:$A, Scoring!$B:$B,"",1)) * (XLOOKUP(V$2, Weightings!$C$2:$C$36, Weightings!$I$2:$I$36,"",1))} -> 2.6 | W4: {=(XLOOKUP(Players!$G3, Scoring!$A:$A, Scoring!$B:$B,"",1)) * (XLOOKUP(W$2, Weightings!$C$2:$C$36, Weightings!$I$2:$I$36,"",1))} -> 1.56 | X4: {=(XLOOKUP(Players!$G3, Scoring!$A:$A, Scoring!$B:$B,"",1)) * (XLOOKUP(X$2, Weightings!$C$2:$C$36, Weightings!$I$2:$I$36,"",1))} -> 2.6 | Y4: {=(XLOOKUP(Players!$G3, Scoring!$A:$A, Scoring!$B:$B,"",1)) * (XLOOKUP(Y$2, Weightings!$C$2:$C$36, Weightings!$I$2:$I$36,"",1))} -> 2.08 | Z4: {=(XLOOKUP(Players!$G3, Scoring!$A:$A, Scoring!$B:$B,"",1)) * (XLOOKUP(Z$2, Weightings!$C$2:$C$36, Weightings!$I$2:$I$36,"",1))} -> 1.56 | AA4: {=(XLOOKUP(Players!$G3, Scoring!$A:$A, Scoring!$B:$B,"",1)) * (XLOOKUP(AA$2, Weightings!$C$2:$C$36, Weightings!$I$2:$I$36,"",1))} -> 2.6 | AB4: {=(XLOOKUP(Players!$H3, Scoring!$A:$A, Scoring!$B:$B,"",1)) * (XLOOKUP(AB$2, Weightings!$C$2:$C$36, Weightings!$I$2:$I$36,"",1))} -> 1.56 | AC4: {=(XLOOKUP(Players!$H3, Scoring!$A:$A, Scoring!$B:$B,"",1)) * (XLOOKUP(AC$2, Weightings!$C$2:$C$36, Weightings!$I$2:$I$36,"",1))} -> 2.6 | AD4: {=(XLOOKUP(Players!$I3, Scoring!$A:$A, Scoring!$B:$B,"",1)) * (XLOOKUP(AD$2, Weightings!$C$2:$C$36, Weightings!$I$2:$I$36,"",1))} -> 2.08 | AE4: {=(XLOOKUP(Players!$I3, Scoring!$A:$A, Scoring!$B:$B,"",1)) * (XLOOKUP(AE$2, Weightings!$C$2:$C$36, Weightings!$I$2:$I$36,"",1))} -> 3.64 | AF4: {=(XLOOKUP(Players!$I3, Scoring!$A:$A, Scoring!$B:$B,"",1)) * (XLOOKUP(AF$2, Weightings!$C$2:$C$36, Weightings!$I$2:$I$36,"",1))} -> 1.56 | AG4: {=(XLOOKUP(Players!$I3, Scoring!$A:$A, Scoring!$B:$B,"",1)) * (XLOOKUP(AG$2, Weightings!$C$2:$C$36, Weightings!$I$2:$I$36,"",1))} -> 1.56 | AH4: {=(XLOOKUP(Players!$J3, Scoring!$A:$A, Scoring!$B:$B,"",1)) * (XLOOKUP(AH$2, Weightings!$C$2:$C$36, Weightings!$I$2:$I$36,"",1))} -> 0.72 | AI4: {=(XLOOKUP(Players!$J3, Scoring!$A:$A, Scoring!$B:$B,"",1)) * (XLOOKUP(AI$2, Weightings!$C$2:$C$36, Weightings!$I$2:$I$36,"",1))} -> 0.72 | AJ4: {=(XLOOKUP(Players!$J3, Scoring!$A:$A, Scoring!$B:$B,"",1)) * (XLOOKUP(AJ$2, Weightings!$C$2:$C$36, Weightings!$I$2:$I$36,"",1))} -> 0.18 | AK4: =SUM(A4:AJ4) -> 52.82
A5: Jonny | B5: {=(XLOOKUP(Players!$B4, Scoring!$A:$A, Scoring!$B:$B,"",1)) * (XLOOKUP(B$2, Weightings!$C$2:$C$36, Weightings!$I$2:$I$36,"",1))} -> 2.08 | C5: {=(XLOOKUP(Players!$B4, Scoring!$A:$A, Scoring!$B:$B,"",1)) * (XLOOKUP(C$2, Weightings!$C$2:$C$36, Weightings!$I$2:$I$36,"",1))} -> 1.04 | D5: {=(XLOOKUP(Players!$B4, Scoring!$A:$A, Scoring!$B:$B,"",1)) * (XLOOKUP(D$2, Weightings!$C$2:$C$36, Weightings!$I$2:$I$36,"",1))} -> 0 | E5: {=(XLOOKUP(Players!$B4, Scoring!$A:$A, Scoring!$B:$B,"",1)) * (XLOOKUP(E$2, Weightings!$C$2:$C$36, Weightings!$I$2:$I$36,"",1))} -> 1.04 | F5: {=(XLOOKUP(Players!$C4, Scoring!$A:$A, Scoring!$B:$B,"",1)) * (XLOOKUP(F$2, Weightings!$C$2:$C$36, Weightings!$I$2:$I$36,"",1))} -> 2.6 | G5: {=(XLOOKUP(Players!$C4, Scoring!$A:$A, Scoring!$B:$B,"",1)) * (XLOOKUP(G$2, Weightings!$C$2:$C$36, Weightings!$I$2:$I$36,"",1))} -> 2.6 | H5: {=(XLOOKUP(Players!$C4, Scoring!$A:$A, Scoring!$B:$B,"",1)) * (XLOOKUP(H$2, Weightings!$C$2:$C$36, Weightings!$I$2:$I$36,"",1))} -> 1.04 | I5: {=(XLOOKUP(Players!$D4, Scoring!$A:$A, Scoring!$B:$B,"",1)) * (XLOOKUP(I$2, Weightings!$C$2:$C$36, Weightings!$I$2:$I$36,"",1))} -> 1.04 | J5: {=(XLOOKUP(Players!$D4, Scoring!$A:$A, Scoring!$B:$B,"",1)) * (XLOOKUP(J$2, Weightings!$C$2:$C$36, Weightings!$I$2:$I$36,"",1))} -> 1.04 | K5: {=(XLOOKUP(Players!$D4, Scoring!$A:$A, Scoring!$B:$B,"",1)) * (XLOOKUP(K$2, Weightings!$C$2:$C$36, Weightings!$I$2:$I$36,"",1))} -> 0.52 | L5: {=(XLOOKUP(Players!$D4, Scoring!$A:$A, Scoring!$B:$B,"",1)) * (XLOOKUP(L$2, Weightings!$C$2:$C$36, Weightings!$I$2:$I$36,"",1))} -> 1.56 | M5: {=(XLOOKUP(Players!$E4, Scoring!$A:$A, Scoring!$B:$B,"",1)) * (XLOOKUP(M$2, Weightings!$C$2:$C$36, Weightings!$I$2:$I$36,"",1))} -> 1.56 | N5: {=(XLOOKUP(Players!$E4, Scoring!$A:$A, Scoring!$B:$B,"",1)) * (XLOOKUP(N$2, Weightings!$C$2:$C$36, Weightings!$I$2:$I$36,"",1))} -> 0 | O5: {=(XLOOKUP(Players!$E4, Scoring!$A:$A, Scoring!$B:$B,"",1)) * (XLOOKUP(O$2, Weightings!$C$2:$C$36, Weightings!$I$2:$I$36,"",1))} -> 0 | P5: {=(XLOOKUP(Players!$E4, Scoring!$A:$A, Scoring!$B:$B,"",1)) * (XLOOKUP(P$2, Weightings!$C$2:$C$36, Weightings!$I$2:$I$36,"",1))} -> 0 | Q5: {=(XLOOKUP(Players!$E4, Scoring!$A:$A, Scoring!$B:$B,"",1)) * (XLOOKUP(Q$2, Weightings!$C$2:$C$36, Weightings!$I$2:$I$36,"",1))} -> 0 | R5: {=(XLOOKUP(Players!$F4, Scoring!$A:$A, Scoring!$B:$B,"",1)) * (XLOOKUP(R$2, Weightings!$C$2:$C$36, Weightings!$I$2:$I$36,"",1))} -> 1.56 | S5: {=(XLOOKUP(Players!$F4, Scoring!$A:$A, Scoring!$B:$B,"",1)) * (XLOOKUP(S$2, Weightings!$C$2:$C$36, Weightings!$I$2:$I$36,"",1))} -> 0.52 | T5: {=(XLOOKUP(Players!$F4, Scoring!$A:$A, Scoring!$B:$B,"",1)) * (XLOOKUP(T$2, Weightings!$C$2:$C$36, Weightings!$I$2:$I$36,"",1))} -> 2.08 | U5: {=(XLOOKUP(Players!$F4, Scoring!$A:$A, Scoring!$B:$B,"",1)) * (XLOOKUP(U$2, Weightings!$C$2:$C$36, Weightings!$I$2:$I$36,"",1))} -> 1.04 | V5: {=(XLOOKUP(Players!$G4, Scoring!$A:$A, Scoring!$B:$B,"",1)) * (XLOOKUP(V$2, Weightings!$C$2:$C$36, Weightings!$I$2:$I$36,"",1))} -> 1.75 | W5: {=(XLOOKUP(Players!$G4, Scoring!$A:$A, Scoring!$B:$B,"",1)) * (XLOOKUP(W$2, Weightings!$C$2:$C$36, Weightings!$I$2:$I$36,"",1))} -> 1.05 | X5: {=(XLOOKUP(Players!$G4, Scoring!$A:$A, Scoring!$B:$B,"",1)) * (XLOOKUP(X$2, Weightings!$C$2:$C$36, Weightings!$I$2:$I$36,"",1))} -> 1.75 | Y5: {=(XLOOKUP(Players!$G4, Scoring!$A:$A, Scoring!$B:$B,"",1)) * (XLOOKUP(Y$2, Weightings!$C$2:$C$36, Weightings!$I$2:$I$36,"",1))} -> 1.4 | Z5: {=(XLOOKUP(Players!$G4, Scoring!$A:$A, Scoring!$B:$B,"",1)) * (XLOOKUP(Z$2, Weightings!$C$2:$C$36, Weightings!$I$2:$I$36,"",1))} -> 1.05 | AA5: {=(XLOOKUP(Players!$G4, Scoring!$A:$A, Scoring!$B:$B,"",1)) * (XLOOKUP(AA$2, Weightings!$C$2:$C$36, Weightings!$I$2:$I$36,"",1))} -> 1.75 | AB5: {=(XLOOKUP(Players!$H4, Scoring!$A:$A, Scoring!$B:$B,"",1)) * (XLOOKUP(AB$2, Weightings!$C$2:$C$36, Weightings!$I$2:$I$36,"",1))} -> 2.1 | AC5: {=(XLOOKUP(Players!$H4, Scoring!$A:$A, Scoring!$B:$B,"",1)) * (XLOOKUP(AC$2, Weightings!$C$2:$C$36, Weightings!$I$2:$I$36,"",1))} -> 3.5 | AD5: {=(XLOOKUP(Players!$I4, Scoring!$A:$A, Scoring!$B:$B,"",1)) * (XLOOKUP(AD$2, Weightings!$C$2:$C$36, Weightings!$I$2:$I$36,"",1))} -> 2.08 | AE5: {=(XLOOKUP(Players!$I4, Scoring!$A:$A, Scoring!$B:$B,"",1)) * (XLOOKUP(AE$2, Weightings!$C$2:$C$36, Weightings!$I$2:$I$36,"",1))} -> 3.64 | AF5: {=(XLOOKUP(Players!$I4, Scoring!$A:$A, Scoring!$B:$B,"",1)) * (XLOOKUP(AF$2, Weightings!$C$2:$C$36, Weightings!$I$2:$I$36,"",1))} -> 1.56 | AG5: {=(XLOOKUP(Players!$I4, Scoring!$A:$A, Scoring!$B:$B,"",1)) * (XLOOKUP(AG$2, Weightings!$C$2:$C$36, Weightings!$I$2:$I$36,"",1))} -> 1.56 | AH5: {=(XLOOKUP(Players!$J4, Scoring!$A:$A, Scoring!$B:$B,"",1)) * (XLOOKUP(AH$2, Weightings!$C$2:$C$36, Weightings!$I$2:$I$36,"",1))} -> 2.08 | AI5: {=(XLOOKUP(Players!$J4, Scoring!$A:$A, Scoring!$B:$B,"",1)) * (XLOOKUP(AI$2, Weightings!$C$2:$C$36, Weightings!$I$2:$I$36,"",1))} -> 2.08 | AJ5: {=(XLOOKUP(Players!$J4, Scoring!$A:$A, Scoring!$B:$B,"",1)) * (XLOOKUP(AJ$2, Weightings!$C$2:$C$36, Weightings!$I$2:$I$36,"",1))} -> 0.52 | AK5: =SUM(A5:AJ5) -> 49.19
A6: Cooper | B6: {=(XLOOKUP(Players!$B5, Scoring!$A:$A, Scoring!$B:$B,"",1)) * (XLOOKUP(B$2, Weightings!$C$2:$C$36, Weightings!$I$2:$I$36,"",1))} -> 1.4 | C6: {=(XLOOKUP(Players!$B5, Scoring!$A:$A, Scoring!$B:$B,"",1)) * (XLOOKUP(C$2, Weightings!$C$2:$C$36, Weightings!$I$2:$I$36,"",1))} -> 0.7 | D6: {=(XLOOKUP(Players!$B5, Scoring!$A:$A, Scoring!$B:$B,"",1)) * (XLOOKUP(D$2, Weightings!$C$2:$C$36, Weightings!$I$2:$I$36,"",1))} -> 0 | E6: {=(XLOOKUP(Players!$B5, Scoring!$A:$A, Scoring!$B:$B,"",1)) * (XLOOKUP(E$2, Weightings!$C$2:$C$36, Weightings!$I$2:$I$36,"",1))} -> 0.7 | F6: {=(XLOOKUP(Players!$C5, Scoring!$A:$A, Scoring!$B:$B,"",1)) * (XLOOKUP(F$2, Weightings!$C$2:$C$36, Weightings!$I$2:$I$36,"",1))} -> 2.6 | G6: {=(XLOOKUP(Players!$C5, Scoring!$A:$A, Scoring!$B:$B,"",1)) * (XLOOKUP(G$2, Weightings!$C$2:$C$36, Weightings!$I$2:$I$36,"",1))} -> 2.6 | H6: {=(XLOOKUP(Players!$C5, Scoring!$A:$A, Scoring!$B:$B,"",1)) * (XLOOKUP(H$2, Weightings!$C$2:$C$36, Weightings!$I$2:$I$36,"",1))} -> 1.04 | I6: {=(XLOOKUP(Players!$D5, Scoring!$A:$A, Scoring!$B:$B,"",1)) * (XLOOKUP(I$2, Weightings!$C$2:$C$36, Weightings!$I$2:$I$36,"",1))} -> 1.04 | J6: {=(XLOOKUP(Players!$D5, Scoring!$A:$A, Scoring!$B:$B,"",1)) * (XLOOKUP(J$2, Weightings!$C$2:$C$36, Weightings!$I$2:$I$36,"",1))} -> 1.04 | K6: {=(XLOOKUP(Players!$D5, Scoring!$A:$A, Scoring!$B:$B,"",1)) * (XLOOKUP(K$2, Weightings!$C$2:$C$36, Weightings!$I$2:$I$36,"",1))} -> 0.52 | L6: {=(XLOOKUP(Players!$D5, Scoring!$A:$A, Scoring!$B:$B,"",1)) * (XLOOKUP(L$2, Weightings!$C$2:$C$36, Weightings!$I$2:$I$36,"",1))} -> 1.56 | M6: {=(XLOOKUP(Players!$E5, Scoring!$A:$A, Scoring!$B:$B,"",1)) * (XLOOKUP(M$2, Weightings!$C$2:$C$36, Weightings!$I$2:$I$36,"",1))} -> 1.05 | N6: {=(XLOOKUP(Players!$E5, Scoring!$A:$A, Scoring!$B:$B,"",1)) * (XLOOKUP(N$2, Weightings!$C$2:$C$36, Weightings!$I$2:$I$36,"",1))} -> 0 | O6: {=(XLOOKUP(Players!$E5, Scoring!$A:$A, Scoring!$B:$B,"",1)) * (XLOOKUP(O$2, Weightings!$C$2:$C$36, Weightings!$I$2:$I$36,"",1))} -> 0 | P6: {=(XLOOKUP(Players!$E5, Scoring!$A:$A, Scoring!$B:$B,"",1)) * (XLOOKUP(P$2, Weightings!$C$2:$C$36, Weightings!$I$2:$I$36,"",1))} -> 0 | Q6: {=(XLOOKUP(Players!$E5, Scoring!$A:$A, Scoring!$B:$B,"",1)) * (XLOOKUP(Q$2, Weightings!$C$2:$C$36, Weightings!$I$2:$I$36,"",1))} -> 0 | R6: {=(XLOOKUP(Players!$F5, Scoring!$A:$A, Scoring!$B:$B,"",1)) * (XLOOKUP(R$2, Weightings!$C$2:$C$36, Weightings!$I$2:$I$36,"",1))} -> 2.1 | S6: {=(XLOOKUP(Players!$F5, Scoring!$A:$A, Scoring!$B:$B,"",1)) * (XLOOKUP(S$2, Weightings!$C$2:$C$36, Weightings!$I$2:$I$36,"",1))} -> 0.7 | T6: {=(XLOOKUP(Players!$F5, Scoring!$A:$A, Scoring!$B:$B,"",1)) * (XLOOKUP(T$2, Weightings!$C$2:$C$36, Weightings!$I$2:$I$36,"",1))} -> 2.8 | U6: {=(XLOOKUP(Players!$F5, Scoring!$A:$A, Scoring!$B:$B,"",1)) * (XLOOKUP(U$2, Weightings!$C$2:$C$36, Weightings!$I$2:$I$36,"",1))} -> 1.4 | V6: {=(XLOOKUP(Players!$G5, Scoring!$A:$A, Scoring!$B:$B,"",1)) * (XLOOKUP(V$2, Weightings!$C$2:$C$36, Weightings!$I$2:$I$36,"",1))} -> 2.6 | W6: {=(XLOOKUP(Players!$G5, Scoring!$A:$A, Scoring!$B:$B,"",1)) * (XLOOKUP(W$2, Weightings!$C$2:$C$36, Weightings!$I$2:$I$36,"",1))} -> 1.56 | X6: {=(XLOOKUP(Players!$G5, Scoring!$A:$A, Scoring!$B:$B,"",1)) * (XLOOKUP(X$2, Weightings!$C$2:$C$36, Weightings!$I$2:$I$36,"",1))} -> 2.6 | Y6: {=(XLOOKUP(Players!$G5, Scoring!$A:$A, Scoring!$B:$B,"",1)) * (XLOOKUP(Y$2, Weightings!$C$2:$C$36, Weightings!$I$2:$I$36,"",1))} -> 2.08 | Z6: {=(XLOOKUP(Players!$G5, Scoring!$A:$A, Scoring!$B:$B,"",1)) * (XLOOKUP(Z$2, Weightings!$C$2:$C$36, Weightings!$I$2:$I$36,"",1))} -> 1.56 | AA6: {=(XLOOKUP(Players!$G5, Scoring!$A:$A, Scoring!$B:$B,"",1)) * (XLOOKUP(AA$2, Weightings!$C$2:$C$36, Weightings!$I$2:$I$36,"",1))} -> 2.6 | AB6: {=(XLOOKUP(Players!$H5, Scoring!$A:$A, Scoring!$B:$B,"",1)) * (XLOOKUP(AB$2, Weightings!$C$2:$C$36, Weightings!$I$2:$I$36,"",1))} -> 1.56 | AC6: {=(XLOOKUP(Players!$H5, Scoring!$A:$A, Scoring!$B:$B,"",1)) * (XLOOKUP(AC$2, Weightings!$C$2:$C$36, Weightings!$I$2:$I$36,"",1))} -> 2.6 | AD6: {=(XLOOKUP(Players!$I5, Scoring!$A:$A, Scoring!$B:$B,"",1)) * (XLOOKUP(AD$2, Weightings!$C$2:$C$36, Weightings!$I$2:$I$36,"",1))} -> 2.8 | AE6: {=(XLOOKUP(Players!$I5, Scoring!$A:$A, Scoring!$B:$B,"",1)) * (XLOOKUP(AE$2, Weightings!$C$2:$C$36, Weightings!$I$2:$I$36,"",1))} -> 4.9 | AF6: {=(XLOOKUP(Players!$I5, Scoring!$A:$A, Scoring!$B:$B,"",1)) * (XLOOKUP(AF$2, Weightings!$C$2:$C$36, Weightings!$I$2:$I$36,"",1))} -> 2.1 | AG6: {=(XLOOKUP(Players!$I5, Scoring!$A:$A, Scoring!$B:$B,"",1)) * (XLOOKUP(AG$2, Weightings!$C$2:$C$36, Weightings!$I$2:$I$36,"",1))} -> 2.1 | AH6: {=(XLOOKUP(Players!$J5, Scoring!$A:$A, Scoring!$B:$B,"",1)) * (XLOOKUP(AH$2, Weightings!$C$2:$C$36, Weightings!$I$2:$I$36,"",1))} -> 1.4 | AI6: {=(XLOOKUP(Players!$J5, Scoring!$A:$A, Scoring!$B:$B,"",1)) * (XLOOKUP(AI$2, Weightings!$C$2:$C$36, Weightings!$I$2:$I$36,"",1))} -> 1.4 | AJ6: {=(XLOOKUP(Players!$J5, Scoring!$A:$A, Scoring!$B:$B,"",1)) * (XLOOKUP(AJ$2, Weightings!$C$2:$C$36, Weightings!$I$2:$I$36,"",1))} -> 0.35 | AK6: =SUM(A6:AJ6) -> 53.46
A7: Michael | B7: {=(XLOOKUP(Players!$B6, Scoring!$A:$A, Scoring!$B:$B,"",1)) * (XLOOKUP(B$2, Weightings!$C$2:$C$36, Weightings!$I$2:$I$36,"",1))} -> 2.08 | C7: {=(XLOOKUP(Players!$B6, Scoring!$A:$A, Scoring!$B:$B,"",1)) * (XLOOKUP(C$2, Weightings!$C$2:$C$36, Weightings!$I$2:$I$36,"",1))} -> 1.04 | D7: {=(XLOOKUP(Players!$B6, Scoring!$A:$A, Scoring!$B:$B,"",1)) * (XLOOKUP(D$2, Weightings!$C$2:$C$36, Weightings!$I$2:$I$36,"",1))} -> 0 | E7: {=(XLOOKUP(Players!$B6, Scoring!$A:$A, Scoring!$B:$B,"",1)) * (XLOOKUP(E$2, Weightings!$C$2:$C$36, Weightings!$I$2:$I$36,"",1))} -> 1.04 | F7: {=(XLOOKUP(Players!$C6, Scoring!$A:$A, Scoring!$B:$B,"",1)) * (XLOOKUP(F$2, Weightings!$C$2:$C$36, Weightings!$I$2:$I$36,"",1))} -> 2.6 | G7: {=(XLOOKUP(Players!$C6, Scoring!$A:$A, Scoring!$B:$B,"",1)) * (XLOOKUP(G$2, Weightings!$C$2:$C$36, Weightings!$I$2:$I$36,"",1))} -> 2.6 | H7: {=(XLOOKUP(Players!$C6, Scoring!$A:$A, Scoring!$B:$B,"",1)) * (XLOOKUP(H$2, Weightings!$C$2:$C$36, Weightings!$I$2:$I$36,"",1))} -> 1.04 | I7: {=(XLOOKUP(Players!$D6, Scoring!$A:$A, Scoring!$B:$B,"",1)) * (XLOOKUP(I$2, Weightings!$C$2:$C$36, Weightings!$I$2:$I$36,"",1))} -> 1.04 | J7: {=(XLOOKUP(Players!$D6, Scoring!$A:$A, Scoring!$B:$B,"",1)) * (XLOOKUP(J$2, Weightings!$C$2:$C$36, Weightings!$I$2:$I$36,"",1))} -> 1.04 | K7: {=(XLOOKUP(Players!$D6, Scoring!$A:$A, Scoring!$B:$B,"",1)) * (XLOOKUP(K$2, Weightings!$C$2:$C$36, Weightings!$I$2:$I$36,"",1))} -> 0.52 | L7: {=(XLOOKUP(Players!$D6, Scoring!$A:$A, Scoring!$B:$B,"",1)) * (XLOOKUP(L$2, Weightings!$C$2:$C$36, Weightings!$I$2:$I$36,"",1))} -> 1.56 | M7: {=(XLOOKUP(Players!$E6, Scoring!$A:$A, Scoring!$B:$B,"",1)) * (XLOOKUP(M$2, Weightings!$C$2:$C$36, Weightings!$I$2:$I$36,"",1))} -> 1.56 | N7: {=(XLOOKUP(Players!$E6, Scoring!$A:$A, Scoring!$B:$B,"",1)) * (XLOOKUP(N$2, Weightings!$C$2:$C$36, Weightings!$I$2:$I$36,"",1))} -> 0 | O7: {=(XLOOKUP(Players!$E6, Scoring!$A:$A, Scoring!$B:$B,"",1)) * (XLOOKUP(O$2, Weightings!$C$2:$C$36, Weightings!$I$2:$I$36,"",1))} -> 0 | P7: {=(XLOOKUP(Players!$E6, Scoring!$A:$A, Scoring!$B:$B,"",1)) * (XLOOKUP(P$2, Weightings!$C$2:$C$36, Weightings!$I$2:$I$36,"",1))} -> 0 | Q7: {=(XLOOKUP(Players!$E6, Scoring!$A:$A, Scoring!$B:$B,"",1)) * (XLOOKUP(Q$2, Weightings!$C$2:$C$36, Weightings!$I$2:$I$36,"",1))} -> 0 | R7: {=(XLOOKUP(Players!$F6, Scoring!$A:$A, Scoring!$B:$B,"",1)) * (XLOOKUP(R$2, Weightings!$C$2:$C$36, Weightings!$I$2:$I$36,"",1))} -> 1.56 | S7: {=(XLOOKUP(Players!$F6, Scoring!$A:$A, Scoring!$B:$B,"",1)) * (XLOOKUP(S$2, Weightings!$C$2:$C$36, Weightings!$I$2:$I$36,"",1))} -> 0.52 | T7: {=(XLOOKUP(Players!$F6, Scoring!$A:$A, Scoring!$B:$B,"",1)) * (XLOOKUP(T$2, Weightings!$C$2:$C$36, Weightings!$I$2:$I$36,"",1))} -> 2.08 | U7: {=(XLOOKUP(Players!$F6, Scoring!$A:$A, Scoring!$B:$B,"",1)) * (XLOOKUP(U$2, Weightings!$C$2:$C$36, Weightings!$I$2:$I$36,"",1))} -> 1.04 | V7: {=(XLOOKUP(Players!$G6, Scoring!$A:$A, Scoring!$B:$B,"",1)) * (XLOOKUP(V$2, Weightings!$C$2:$C$36, Weightings!$I$2:$I$36,"",1))} -> 1.75 | W7: {=(XLOOKUP(Players!$G6, Scoring!$A:$A, Scoring!$B:$B,"",1)) * (XLOOKUP(W$2, Weightings!$C$2:$C$36, Weightings!$I$2:$I$36,"",1))} -> 1.05 | X7: {=(XLOOKUP(Players!$G6, Scoring!$A:$A, Scoring!$B:$B,"",1)) * (XLOOKUP(X$2, Weightings!$C$2:$C$36, Weightings!$I$2:$I$36,"",1))} -> 1.75 | Y7: {=(XLOOKUP(Players!$G6, Scoring!$A:$A, Scoring!$B:$B,"",1)) * (XLOOKUP(Y$2, Weightings!$C$2:$C$36, Weightings!$I$2:$I$36,"",1))} -> 1.4 | Z7: {=(XLOOKUP(Players!$G6, Scoring!$A:$A, Scoring!$B:$B,"",1)) * (XLOOKUP(Z$2, Weightings!$C$2:$C$36, Weightings!$I$2:$I$36,"",1))} -> 1.05 | AA7: {=(XLOOKUP(Players!$G6, Scoring!$A:$A, Scoring!$B:$B,"",1)) * (XLOOKUP(AA$2, Weightings!$C$2:$C$36, Weightings!$I$2:$I$36,"",1))} -> 1.75 | AB7: {=(XLOOKUP(Players!$H6, Scoring!$A:$A, Scoring!$B:$B,"",1)) * (XLOOKUP(AB$2, Weightings!$C$2:$C$36, Weightings!$I$2:$I$36,"",1))} -> 1.56 | AC7: {=(XLOOKUP(Players!$H6, Scoring!$A:$A, Scoring!$B:$B,"",1)) * (XLOOKUP(AC$2, Weightings!$C$2:$C$36, Weightings!$I$2:$I$36,"",1))} -> 2.6 | AD7: {=(XLOOKUP(Players!$I6, Scoring!$A:$A, Scoring!$B:$B,"",1)) * (XLOOKUP(AD$2, Weightings!$C$2:$C$36, Weightings!$I$2:$I$36,"",1))} -> 2.08 | AE7: {=(XLOOKUP(Players!$I6, Scoring!$A:$A, Scoring!$B:$B,"",1)) * (XLOOKUP(AE$2, Weightings!$C$2:$C$36, Weightings!$I$2:$I$36,"",1))} -> 3.64 | AF7: {=(XLOOKUP(Players!$I6, Scoring!$A:$A, Scoring!$B:$B,"",1)) * (XLOOKUP(AF$2, Weightings!$C$2:$C$36, Weightings!$I$2:$I$36,"",1))} -> 1.56 | AG7: {=(XLOOKUP(Players!$I6, Scoring!$A:$A, Scoring!$B:$B,"",1)) * (XLOOKUP(AG$2, Weightings!$C$2:$C$36, Weightings!$I$2:$I$36,"",1))} -> 1.56 | AH7: {=(XLOOKUP(Players!$J6, Scoring!$A:$A, Scoring!$B:$B,"",1)) * (XLOOKUP(AH$2, Weightings!$C$2:$C$36, Weightings!$I$2:$I$36,"",1))} -> 1.4 | AI7: {=(XLOOKUP(Players!$J6, Scoring!$A:$A, Scoring!$B:$B,"",1)) * (XLOOKUP(AI$2, Weightings!$C$2:$C$36, Weightings!$I$2:$I$36,"",1))} -> 1.4 | AJ7: {=(XLOOKUP(Players!$J6, Scoring!$A:$A, Scoring!$B:$B,"",1)) * (XLOOKUP(AJ$2, Weightings!$C$2:$C$36, Weightings!$I$2:$I$36,"",1))} -> 0.35 | AK7: =SUM(A7:AJ7) -> 46.22
A8: Bryan | B8: {=(XLOOKUP(Players!$B7, Scoring!$A:$A, Scoring!$B:$B,"",1)) * (XLOOKUP(B$2, Weightings!$C$2:$C$36, Weightings!$I$2:$I$36,"",1))} -> 2.08 | C8: {=(XLOOKUP(Players!$B7, Scoring!$A:$A, Scoring!$B:$B,"",1)) * (XLOOKUP(C$2, Weightings!$C$2:$C$36, Weightings!$I$2:$I$36,"",1))} -> 1.04 | D8: {=(XLOOKUP(Players!$B7, Scoring!$A:$A, Scoring!$B:$B,"",1)) * (XLOOKUP(D$2, Weightings!$C$2:$C$36, Weightings!$I$2:$I$36,"",1))} -> 0 | E8: {=(XLOOKUP(Players!$B7, Scoring!$A:$A, Scoring!$B:$B,"",1)) * (XLOOKUP(E$2, Weightings!$C$2:$C$36, Weightings!$I$2:$I$36,"",1))} -> 1.04 | F8: {=(XLOOKUP(Players!$C7, Scoring!$A:$A, Scoring!$B:$B,"",1)) * (XLOOKUP(F$2, Weightings!$C$2:$C$36, Weightings!$I$2:$I$36,"",1))} -> 2.6 | G8: {=(XLOOKUP(Players!$C7, Scoring!$A:$A, Scoring!$B:$B,"",1)) * (XLOOKUP(G$2, Weightings!$C$2:$C$36, Weightings!$I$2:$I$36,"",1))} -> 2.6 | H8: {=(XLOOKUP(Players!$C7, Scoring!$A:$A, Scoring!$B:$B,"",1)) * (XLOOKUP(H$2, Weightings!$C$2:$C$36, Weightings!$I$2:$I$36,"",1))} -> 1.04 | I8: {=(XLOOKUP(Players!$D7, Scoring!$A:$A, Scoring!$B:$B,"",1)) * (XLOOKUP(I$2, Weightings!$C$2:$C$36, Weightings!$I$2:$I$36,"",1))} -> 1.04 | J8: {=(XLOOKUP(Players!$D7, Scoring!$A:$A, Scoring!$B:$B,"",1)) * (XLOOKUP(J$2, Weightings!$C$2:$C$36, Weightings!$I$2:$I$36,"",1))} -> 1.04 | K8: {=(XLOOKUP(Players!$D7, Scoring!$A:$A, Scoring!$B:$B,"",1)) * (XLOOKUP(K$2, Weightings!$C$2:$C$36, Weightings!$I$2:$I$36,"",1))} -> 0.52 | L8: {=(XLOOKUP(Players!$D7, Scoring!$A:$A, Scoring!$B:$B,"",1)) * (XLOOKUP(L$2, Weightings!$C$2:$C$36, Weightings!$I$2:$I$36,"",1))} -> 1.56 | M8: {=(XLOOKUP(Players!$E7, Scoring!$A:$A, Scoring!$B:$B,"",1)) * (XLOOKUP(M$2, Weightings!$C$2:$C$36, Weightings!$I$2:$I$36,"",1))} -> 1.05 | N8: {=(XLOOKUP(Players!$E7, Scoring!$A:$A, Scoring!$B:$B,"",1)) * (XLOOKUP(N$2, Weightings!$C$2:$C$36, Weightings!$I$2:$I$36,"",1))} -> 0 | O8: {=(XLOOKUP(Players!$E7, Scoring!$A:$A, Scoring!$B:$B,"",1)) * (XLOOKUP(O$2, Weightings!$C$2:$C$36, Weightings!$I$2:$I$36,"",1))} -> 0 | P8: {=(XLOOKUP(Players!$E7, Scoring!$A:$A, Scoring!$B:$B,"",1)) * (XLOOKUP(P$2, Weightings!$C$2:$C$36, Weightings!$I$2:$I$36,"",1))} -> 0 | Q8: {=(XLOOKUP(Players!$E7, Scoring!$A:$A, Scoring!$B:$B,"",1)) * (XLOOKUP(Q$2, Weightings!$C$2:$C$36, Weightings!$I$2:$I$36,"",1))} -> 0 | R8: {=(XLOOKUP(Players!$F7, Scoring!$A:$A, Scoring!$B:$B,"",1)) * (XLOOKUP(R$2, Weightings!$C$2:$C$36, Weightings!$I$2:$I$36,"",1))} -> 1.56 | S8: {=(XLOOKUP(Players!$F7, Scoring!$A:$A, Scoring!$B:$B,"",1)) * (XLOOKUP(S$2, Weightings!$C$2:$C$36, Weightings!$I$2:$I$36,"",1))} -> 0.52 | T8: {=(XLOOKUP(Players!$F7, Scoring!$A:$A, Scoring!$B:$B,"",1)) * (XLOOKUP(T$2, Weightings!$C$2:$C$36, Weightings!$I$2:$I$36,"",1))} -> 2.08 | U8: {=(XLOOKUP(Players!$F7, Scoring!$A:$A, Scoring!$B:$B,"",1)) * (XLOOKUP(U$2, Weightings!$C$2:$C$36, Weightings!$I$2:$I$36,"",1))} -> 1.04 | V8: {=(XLOOKUP(Players!$G7, Scoring!$A:$A, Scoring!$B:$B,"",1)) * (XLOOKUP(V$2, Weightings!$C$2:$C$36, Weightings!$I$2:$I$36,"",1))} -> 2.6 | W8: {=(XLOOKUP(Players!$G7, Scoring!$A:$A, Scoring!$B:$B,"",1)) * (XLOOKUP(W$2, Weightings!$C$2:$C$36, Weightings!$I$2:$I$36,"",1))} -> 1.56 | X8: {=(XLOOKUP(Players!$G7, Scoring!$A:$A, Scoring!$B:$B,"",1)) * (XLOOKUP(X$2, Weightings!$C$2:$C$36, Weightings!$I$2:$I$36,"",1))} -> 2.6 | Y8: {=(XLOOKUP(Players!$G7, Scoring!$A:$A, Scoring!$B:$B,"",1)) * (XLOOKUP(Y$2, Weightings!$C$2:$C$36, Weightings!$I$2:$I$36,"",1))} -> 2.08 | Z8: {=(XLOOKUP(Players!$G7, Scoring!$A:$A, Scoring!$B:$B,"",1)) * (XLOOKUP(Z$2, Weightings!$C$2:$C$36, Weightings!$I$2:$I$36,"",1))} -> 1.56 | AA8: {=(XLOOKUP(Players!$G7, Scoring!$A:$A, Scoring!$B:$B,"",1)) * (XLOOKUP(AA$2, Weightings!$C$2:$C$36, Weightings!$I$2:$I$36,"",1))} -> 2.6 | AB8: {=(XLOOKUP(Players!$H7, Scoring!$A:$A, Scoring!$B:$B,"",1)) * (XLOOKUP(AB$2, Weightings!$C$2:$C$36, Weightings!$I$2:$I$36,"",1))} -> 1.56 | AC8: {=(XLOOKUP(Players!$H7, Scoring!$A:$A, Scoring!$B:$B,"",1)) * (XLOOKUP(AC$2, Weightings!$C$2:$C$36, Weightings!$I$2:$I$36,"",1))} -> 2.6 | AD8: {=(XLOOKUP(Players!$I7, Scoring!$A:$A, Scoring!$B:$B,"",1)) * (XLOOKUP(AD$2, Weightings!$C$2:$C$36, Weightings!$I$2:$I$36,"",1))} -> 2.08 | AE8: {=(XLOOKUP(Players!$I7, Scoring!$A:$A, Scoring!$B:$B,"",1)) * (XLOOKUP(AE$2, Weightings!$C$2:$C$36, Weightings!$I$2:$I$36,"",1))} -> 3.64 | AF8: {=(XLOOKUP(Players!$I7, Scoring!$A:$A, Scoring!$B:$B,"",1)) * (XLOOKUP(AF$2, Weightings!$C$2:$C$36, Weightings!$I$2:$I$36,"",1))} -> 1.56 | AG8: {=(XLOOKUP(Players!$I7, Scoring!$A:$A, Scoring!$B:$B,"",1)) * (XLOOKUP(AG$2, Weightings!$C$2:$C$36, Weightings!$I$2:$I$36,"",1))} -> 1.56 | AH8: {=(XLOOKUP(Players!$J7, Scoring!$A:$A, Scoring!$B:$B,"",1)) * (XLOOKUP(AH$2, Weightings!$C$2:$C$36, Weightings!$I$2:$I$36,"",1))} -> 1.4 | AI8: {=(XLOOKUP(Players!$J7, Scoring!$A:$A, Scoring!$B:$B,"",1)) * (XLOOKUP(AI$2, Weightings!$C$2:$C$36, Weightings!$I$2:$I$36,"",1))} -> 1.4 | AJ8: {=(XLOOKUP(Players!$J7, Scoring!$A:$A, Scoring!$B:$B,"",1)) * (XLOOKUP(AJ$2, Weightings!$C$2:$C$36, Weightings!$I$2:$I$36,"",1))} -> 0.35 | AK8: =SUM(A8:AJ8) -> 49.96
A9: Cairan | B9: {=(XLOOKUP(Players!$B8, Scoring!$A:$A, Scoring!$B:$B,"",1)) * (XLOOKUP(B$2, Weightings!$C$2:$C$36, Weightings!$I$2:$I$36,"",1))} -> 2.08 | C9: {=(XLOOKUP(Players!$B8, Scoring!$A:$A, Scoring!$B:$B,"",1)) * (XLOOKUP(C$2, Weightings!$C$2:$C$36, Weightings!$I$2:$I$36,"",1))} -> 1.04 | D9: {=(XLOOKUP(Players!$B8, Scoring!$A:$A, Scoring!$B:$B,"",1)) * (XLOOKUP(D$2, Weightings!$C$2:$C$36, Weightings!$I$2:$I$36,"",1))} -> 0 | E9: {=(XLOOKUP(Players!$B8, Scoring!$A:$A, Scoring!$B:$B,"",1)) * (XLOOKUP(E$2, Weightings!$C$2:$C$36, Weightings!$I$2:$I$36,"",1))} -> 1.04 | F9: {=(XLOOKUP(Players!$C8, Scoring!$A:$A, Scoring!$B:$B,"",1)) * (XLOOKUP(F$2, Weightings!$C$2:$C$36, Weightings!$I$2:$I$36,"",1))} -> 2.6 | G9: {=(XLOOKUP(Players!$C8, Scoring!$A:$A, Scoring!$B:$B,"",1)) * (XLOOKUP(G$2, Weightings!$C$2:$C$36, Weightings!$I$2:$I$36,"",1))} -> 2.6 | H9: {=(XLOOKUP(Players!$C8, Scoring!$A:$A, Scoring!$B:$B,"",1)) * (XLOOKUP(H$2, Weightings!$C$2:$C$36, Weightings!$I$2:$I$36,"",1))} -> 1.04 | I9: {=(XLOOKUP(Players!$D8, Scoring!$A:$A, Scoring!$B:$B,"",1)) * (XLOOKUP(I$2, Weightings!$C$2:$C$36, Weightings!$I$2:$I$36,"",1))} -> 1.04 | J9: {=(XLOOKUP(Players!$D8, Scoring!$A:$A, Scoring!$B:$B,"",1)) * (XLOOKUP(J$2, Weightings!$C$2:$C$36, Weightings!$I$2:$I$36,"",1))} -> 1.04 | K9: {=(XLOOKUP(Players!$D8, Scoring!$A:$A, Scoring!$B:$B,"",1)) * (XLOOKUP(K$2, Weightings!$C$2:$C$36, Weightings!$I$2:$I$36,"",1))} -> 0.52 | L9: {=(XLOOKUP(Players!$D8, Scoring!$A:$A, Scoring!$B:$B,"",1)) * (XLOOKUP(L$2, Weightings!$C$2:$C$36, Weightings!$I$2:$I$36,"",1))} -> 1.56 | M9: {=(XLOOKUP(Players!$E8, Scoring!$A:$A, Scoring!$B:$B,"",1)) * (XLOOKUP(M$2, Weightings!$C$2:$C$36, Weightings!$I$2:$I$36,"",1))} -> 1.56 | N9: {=(XLOOKUP(Players!$E8, Scoring!$A:$A, Scoring!$B:$B,"",1)) * (XLOOKUP(N$2, Weightings!$C$2:$C$36, Weightings!$I$2:$I$36,"",1))} -> 0 | O9: {=(XLOOKUP(Players!$E8, Scoring!$A:$A, Scoring!$B:$B,"",1)) * (XLOOKUP(O$2, Weightings!$C$2:$C$36, Weightings!$I$2:$I$36,"",1))} -> 0 | P9: {=(XLOOKUP(Players!$E8, Scoring!$A:$A, Scoring!$B:$B,"",1)) * (XLOOKUP(P$2, Weightings!$C$2:$C$36, Weightings!$I$2:$I$36,"",1))} -> 0 | Q9: {=(XLOOKUP(Players!$E8, Scoring!$A:$A, Scoring!$B:$B,"",1)) * (XLOOKUP(Q$2, Weightings!$C$2:$C$36, Weightings!$I$2:$I$36,"",1))} -> 0 | R9: {=(XLOOKUP(Players!$F8, Scoring!$A:$A, Scoring!$B:$B,"",1)) * (XLOOKUP(R$2, Weightings!$C$2:$C$36, Weightings!$I$2:$I$36,"",1))} -> 1.56 | S9: {=(XLOOKUP(Players!$F8, Scoring!$A:$A, Scoring!$B:$B,"",1)) * (XLOOKUP(S$2, Weightings!$C$2:$C$36, Weightings!$I$2:$I$36,"",1))} -> 0.52 | T9: {=(XLOOKUP(Players!$F8, Scoring!$A:$A, Scoring!$B:$B,"",1)) * (XLOOKUP(T$2, Weightings!$C$2:$C$36, Weightings!$I$2:$I$36,"",1))} -> 2.08 | U9: {=(XLOOKUP(Players!$F8, Scoring!$A:$A, Scoring!$B:$B,"",1)) * (XLOOKUP(U$2, Weightings!$C$2:$C$36, Weightings!$I$2:$I$36,"",1))} -> 1.04 | V9: {=(XLOOKUP(Players!$G8, Scoring!$A:$A, Scoring!$B:$B,"",1)) * (XLOOKUP(V$2, Weightings!$C$2:$C$36, Weightings!$I$2:$I$36,"",1))} -> 2.6 | W9: {=(XLOOKUP(Players!$G8, Scoring!$A:$A, Scoring!$B:$B,"",1)) * (XLOOKUP(W$2, Weightings!$C$2:$C$36, Weightings!$I$2:$I$36,"",1))} -> 1.56 | X9: {=(XLOOKUP(Players!$G8, Scoring!$A:$A, Scoring!$B:$B,"",1)) * (XLOOKUP(X$2, Weightings!$C$2:$C$36, Weightings!$I$2:$I$36,"",1))} -> 2.6 | Y9: {=(XLOOKUP(Players!$G8, Scoring!$A:$A, Scoring!$B:$B,"",1)) * (XLOOKUP(Y$2, Weightings!$C$2:$C$36, Weightings!$I$2:$I$36,"",1))} -> 2.08 | Z9: {=(XLOOKUP(Players!$G8, Scoring!$A:$A, Scoring!$B:$B,"",1)) * (XLOOKUP(Z$2, Weightings!$C$2:$C$36, Weightings!$I$2:$I$36,"",1))} -> 1.56 | AA9: {=(XLOOKUP(Players!$G8, Scoring!$A:$A, Scoring!$B:$B,"",1)) * (XLOOKUP(AA$2, Weightings!$C$2:$C$36, Weightings!$I$2:$I$36,"",1))} -> 2.6 | AB9: {=(XLOOKUP(Players!$H8, Scoring!$A:$A, Scoring!$B:$B,"",1)) * (XLOOKUP(AB$2, Weightings!$C$2:$C$36, Weightings!$I$2:$I$36,"",1))} -> 1.56 | AC9: {=(XLOOKUP(Players!$H8, Scoring!$A:$A, Scoring!$B:$B,"",1)) * (XLOOKUP(AC$2, Weightings!$C$2:$C$36, Weightings!$I$2:$I$36,"",1))} -> 2.6 | AD9: {=(XLOOKUP(Players!$I8, Scoring!$A:$A, Scoring!$B:$B,"",1)) * (XLOOKUP(AD$2, Weightings!$C$2:$C$36, Weightings!$I$2:$I$36,"",1))} -> 2.8 | AE9: {=(XLOOKUP(Players!$I8, Scoring!$A:$A, Scoring!$B:$B,"",1)) * (XLOOKUP(AE$2, Weightings!$C$2:$C$36, Weightings!$I$2:$I$36,"",1))} -> 4.9 | AF9: {=(XLOOKUP(Players!$I8, Scoring!$A:$A, Scoring!$B:$B,"",1)) * (XLOOKUP(AF$2, Weightings!$C$2:$C$36, Weightings!$I$2:$I$36,"",1))} -> 2.1 | AG9: {=(XLOOKUP(Players!$I8, Scoring!$A:$A, Scoring!$B:$B,"",1)) * (XLOOKUP(AG$2, Weightings!$C$2:$C$36, Weightings!$I$2:$I$36,"",1))} -> 2.1 | AH9: {=(XLOOKUP(Players!$J8, Scoring!$A:$A, Scoring!$B:$B,"",1)) * (XLOOKUP(AH$2, Weightings!$C$2:$C$36, Weightings!$I$2:$I$36,"",1))} -> 1.4 | AI9: {=(XLOOKUP(Players!$J8, Scoring!$A:$A, Scoring!$B:$B,"",1)) * (XLOOKUP(AI$2, Weightings!$C$2:$C$36, Weightings!$I$2:$I$36,"",1))} -> 1.4 | AJ9: {=(XLOOKUP(Players!$J8, Scoring!$A:$A, Scoring!$B:$B,"",1)) * (XLOOKUP(AJ$2, Weightings!$C$2:$C$36, Weightings!$I$2:$I$36,"",1))} -> 0.35 | AK9: =SUM(A9:AJ9) -> 53.53
A10: James | B10: {=(XLOOKUP(Players!$B9, Scoring!$A:$A, Scoring!$B:$B,"",1)) * (XLOOKUP(B$2, Weightings!$C$2:$C$36, Weightings!$I$2:$I$36,"",1))} -> 2.08 | C10: {=(XLOOKUP(Players!$B9, Scoring!$A:$A, Scoring!$B:$B,"",1)) * (XLOOKUP(C$2, Weightings!$C$2:$C$36, Weightings!$I$2:$I$36,"",1))} -> 1.04 | D10: {=(XLOOKUP(Players!$B9, Scoring!$A:$A, Scoring!$B:$B,"",1)) * (XLOOKUP(D$2, Weightings!$C$2:$C$36, Weightings!$I$2:$I$36,"",1))} -> 0 | E10: {=(XLOOKUP(Players!$B9, Scoring!$A:$A, Scoring!$B:$B,"",1)) * (XLOOKUP(E$2, Weightings!$C$2:$C$36, Weightings!$I$2:$I$36,"",1))} -> 1.04 | F10: {=(XLOOKUP(Players!$C9, Scoring!$A:$A, Scoring!$B:$B,"",1)) * (XLOOKUP(F$2, Weightings!$C$2:$C$36, Weightings!$I$2:$I$36,"",1))} -> 2.6 | G10: {=(XLOOKUP(Players!$C9, Scoring!$A:$A, Scoring!$B:$B,"",1)) * (XLOOKUP(G$2, Weightings!$C$2:$C$36, Weightings!$I$2:$I$36,"",1))} -> 2.6 | H10: {=(XLOOKUP(Players!$C9, Scoring!$A:$A, Scoring!$B:$B,"",1)) * (XLOOKUP(H$2, Weightings!$C$2:$C$36, Weightings!$I$2:$I$36,"",1))} -> 1.04 | I10: {=(XLOOKUP(Players!$D9, Scoring!$A:$A, Scoring!$B:$B,"",1)) * (XLOOKUP(I$2, Weightings!$C$2:$C$36, Weightings!$I$2:$I$36,"",1))} -> 0.7 | J10: {=(XLOOKUP(Players!$D9, Scoring!$A:$A, Scoring!$B:$B,"",1)) * (XLOOKUP(J$2, Weightings!$C$2:$C$36, Weightings!$I$2:$I$36,"",1))} -> 0.7 | K10: {=(XLOOKUP(Players!$D9, Scoring!$A:$A, Scoring!$B:$B,"",1)) * (XLOOKUP(K$2, Weightings!$C$2:$C$36, Weightings!$I$2:$I$36,"",1))} -> 0.35 | L10: {=(XLOOKUP(Players!$D9, Scoring!$A:$A, Scoring!$B:$B,"",1)) * (XLOOKUP(L$2, Weightings!$C$2:$C$36, Weightings!$I$2:$I$36,"",1))} -> 1.05 | M10: {=(XLOOKUP(Players!$E9, Scoring!$A:$A, Scoring!$B:$B,"",1)) * (XLOOKUP(M$2, Weightings!$C$2:$C$36, Weightings!$I$2:$I$36,"",1))} -> 1.05 | N10: {=(XLOOKUP(Players!$E9, Scoring!$A:$A, Scoring!$B:$B,"",1)) * (XLOOKUP(N$2, Weightings!$C$2:$C$36, Weightings!$I$2:$I$36,"",1))} -> 0 | O10: {=(XLOOKUP(Players!$E9, Scoring!$A:$A, Scoring!$B:$B,"",1)) * (XLOOKUP(O$2, Weightings!$C$2:$C$36, Weightings!$I$2:$I$36,"",1))} -> 0 | P10: {=(XLOOKUP(Players!$E9, Scoring!$A:$A, Scoring!$B:$B,"",1)) * (XLOOKUP(P$2, Weightings!$C$2:$C$36, Weightings!$I$2:$I$36,"",1))} -> 0 | Q10: {=(XLOOKUP(Players!$E9, Scoring!$A:$A, Scoring!$B:$B,"",1)) * (XLOOKUP(Q$2, Weightings!$C$2:$C$36, Weightings!$I$2:$I$36,"",1))} -> 0 | R10: {=(XLOOKUP(Players!$F9, Scoring!$A:$A, Scoring!$B:$B,"",1)) * (XLOOKUP(R$2, Weightings!$C$2:$C$36, Weightings!$I$2:$I$36,"",1))} -> 1.56 | S10: {=(XLOOKUP(Players!$F9, Scoring!$A:$A, Scoring!$B:$B,"",1)) * (XLOOKUP(S$2, Weightings!$C$2:$C$36, Weightings!$I$2:$I$36,"",1))} -> 0.52 | T10: {=(XLOOKUP(Players!$F9, Scoring!$A:$A, Scoring!$B:$B,"",1)) * (XLOOKUP(T$2, Weightings!$C$2:$C$36, Weightings!$I$2:$I$36,"",1))} -> 2.08 | U10: {=(XLOOKUP(Players!$F9, Scoring!$A:$A, Scoring!$B:$B,"",1)) * (XLOOKUP(U$2, Weightings!$C$2:$C$36, Weightings!$I$2:$I$36,"",1))} -> 1.04 | V10: {=(XLOOKUP(Players!$G9, Scoring!$A:$A, Scoring!$B:$B,"",1)) * (XLOOKUP(V$2, Weightings!$C$2:$C$36, Weightings!$I$2:$I$36,"",1))} -> 2.6 | W10: {=(XLOOKUP(Players!$G9, Scoring!$A:$A, Scoring!$B:$B,"",1)) * (XLOOKUP(W$2, Weightings!$C$2:$C$36, Weightings!$I$2:$I$36,"",1))} -> 1.56 | X10: {=(XLOOKUP(Players!$G9, Scoring!$A:$A, Scoring!$B:$B,"",1)) * (XLOOKUP(X$2, Weightings!$C$2:$C$36, Weightings!$I$2:$I$36,"",1))} -> 2.6 | Y10: {=(XLOOKUP(Players!$G9, Scoring!$A:$A, Scoring!$B:$B,"",1)) * (XLOOKUP(Y$2, Weightings!$C$2:$C$36, Weightings!$I$2:$I$36,"",1))} -> 2.08 | Z10: {=(XLOOKUP(Players!$G9, Scoring!$A:$A, Scoring!$B:$B,"",1)) * (XLOOKUP(Z$2, Weightings!$C$2:$C$36, Weightings!$I$2:$I$36,"",1))} -> 1.56 | AA10: {=(XLOOKUP(Players!$G9, Scoring!$A:$A, Scoring!$B:$B,"",1)) * (XLOOKUP(AA$2, Weightings!$C$2:$C$36, Weightings!$I$2:$I$36,"",1))} -> 2.6 | AB10: {=(XLOOKUP(Players!$H9, Scoring!$A:$A, Scoring!$B:$B,"",1)) * (XLOOKUP(AB$2, Weightings!$C$2:$C$36, Weightings!$I$2:$I$36,"",1))} -> 0.54 | AC10: {=(XLOOKUP(Players!$H9, Scoring!$A:$A, Scoring!$B:$B,"",1)) * (XLOOKUP(AC$2, Weightings!$C$2:$C$36, Weightings!$I$2:$I$36,"",1))} -> 0.9 | AD10: {=(XLOOKUP(Players!$I9, Scoring!$A:$A, Scoring!$B:$B,"",1)) * (XLOOKUP(AD$2, Weightings!$C$2:$C$36, Weightings!$I$2:$I$36,"",1))} -> 1.4 | AE10: {=(XLOOKUP(Players!$I9, Scoring!$A:$A, Scoring!$B:$B,"",1)) * (XLOOKUP(AE$2, Weightings!$C$2:$C$36, Weightings!$I$2:$I$36,"",1))} -> 2.45 | AF10: {=(XLOOKUP(Players!$I9, Scoring!$A:$A, Scoring!$B:$B,"",1)) * (XLOOKUP(AF$2, Weightings!$C$2:$C$36, Weightings!$I$2:$I$36,"",1))} -> 1.05 | AG10: {=(XLOOKUP(Players!$I9, Scoring!$A:$A, Scoring!$B:$B,"",1)) * (XLOOKUP(AG$2, Weightings!$C$2:$C$36, Weightings!$I$2:$I$36,"",1))} -> 1.05 | AH10: {=(XLOOKUP(Players!$J9, Scoring!$A:$A, Scoring!$B:$B,"",1)) * (XLOOKUP(AH$2, Weightings!$C$2:$C$36, Weightings!$I$2:$I$36,"",1))} -> 1.4 | AI10: {=(XLOOKUP(Players!$J9, Scoring!$A:$A, Scoring!$B:$B,"",1)) * (XLOOKUP(AI$2, Weightings!$C$2:$C$36, Weightings!$I$2:$I$36,"",1))} -> 1.4 | AJ10: {=(XLOOKUP(Players!$J9, Scoring!$A:$A, Scoring!$B:$B,"",1)) * (XLOOKUP(AJ$2, Weightings!$C$2:$C$36, Weightings!$I$2:$I$36,"",1))} -> 0.35 | AK10: =SUM(A10:AJ10) -> 42.99
A11: Jayden | B11: {=(XLOOKUP(Players!$B10, Scoring!$A:$A, Scoring!$B:$B,"",1)) * (XLOOKUP(B$2, Weightings!$C$2:$C$36, Weightings!$I$2:$I$36,"",1))} -> 2.08 | C11: {=(XLOOKUP(Players!$B10, Scoring!$A:$A, Scoring!$B:$B,"",1)) * (XLOOKUP(C$2, Weightings!$C$2:$C$36, Weightings!$I$2:$I$36,"",1))} -> 1.04 | D11: {=(XLOOKUP(Players!$B10, Scoring!$A:$A, Scoring!$B:$B,"",1)) * (XLOOKUP(D$2, Weightings!$C$2:$C$36, Weightings!$I$2:$I$36,"",1))} -> 0 | E11: {=(XLOOKUP(Players!$B10, Scoring!$A:$A, Scoring!$B:$B,"",1)) * (XLOOKUP(E$2, Weightings!$C$2:$C$36, Weightings!$I$2:$I$36,"",1))} -> 1.04 | F11: {=(XLOOKUP(Players!$C10, Scoring!$A:$A, Scoring!$B:$B,"",1)) * (XLOOKUP(F$2, Weightings!$C$2:$C$36, Weightings!$I$2:$I$36,"",1))} -> 2.6 | G11: {=(XLOOKUP(Players!$C10, Scoring!$A:$A, Scoring!$B:$B,"",1)) * (XLOOKUP(G$2, Weightings!$C$2:$C$36, Weightings!$I$2:$I$36,"",1))} -> 2.6 | H11: {=(XLOOKUP(Players!$C10, Scoring!$A:$A, Scoring!$B:$B,"",1)) * (XLOOKUP(H$2, Weightings!$C$2:$C$36, Weightings!$I$2:$I$36,"",1))} -> 1.04 | I11: {=(XLOOKUP(Players!$D10, Scoring!$A:$A, Scoring!$B:$B,"",1)) * (XLOOKUP(I$2, Weightings!$C$2:$C$36, Weightings!$I$2:$I$36,"",1))} -> 1.04 | J11: {=(XLOOKUP(Players!$D10, Scoring!$A:$A, Scoring!$B:$B,"",1)) * (XLOOKUP(J$2, Weightings!$C$2:$C$36, Weightings!$I$2:$I$36,"",1))} -> 1.04 | K11: {=(XLOOKUP(Players!$D10, Scoring!$A:$A, Scoring!$B:$B,"",1)) * (XLOOKUP(K$2, Weightings!$C$2:$C$36, Weightings!$I$2:$I$36,"",1))} -> 0.52 | L11: {=(XLOOKUP(Players!$D10, Scoring!$A:$A, Scoring!$B:$B,"",1)) * (XLOOKUP(L$2, Weightings!$C$2:$C$36, Weightings!$I$2:$I$36,"",1))} -> 1.56 | M11: {=(XLOOKUP(Players!$E10, Scoring!$A:$A, Scoring!$B:$B,"",1)) * (XLOOKUP(M$2, Weightings!$C$2:$C$36, Weightings!$I$2:$I$36,"",1))} -> 1.05 | N11: {=(XLOOKUP(Players!$E10, Scoring!$A:$A, Scoring!$B:$B,"",1)) * (XLOOKUP(N$2, Weightings!$C$2:$C$36, Weightings!$I$2:$I$36,"",1))} -> 0 | O11: {=(XLOOKUP(Players!$E10, Scoring!$A:$A, Scoring!$B:$B,"",1)) * (XLOOKUP(O$2, Weightings!$C$2:$C$36, Weightings!$I$2:$I$36,"",1))} -> 0 | P11: {=(XLOOKUP(Players!$E10, Scoring!$A:$A, Scoring!$B:$B,"",1)) * (XLOOKUP(P$2, Weightings!$C$2:$C$36, Weightings!$I$2:$I$36,"",1))} -> 0 | Q11: {=(XLOOKUP(Players!$E10, Scoring!$A:$A, Scoring!$B:$B,"",1)) * (XLOOKUP(Q$2, Weightings!$C$2:$C$36, Weightings!$I$2:$I$36,"",1))} -> 0 | R11: {=(XLOOKUP(Players!$F10, Scoring!$A:$A, Scoring!$B:$B,"",1)) * (XLOOKUP(R$2, Weightings!$C$2:$C$36, Weightings!$I$2:$I$36,"",1))} -> 1.56 | S11: {=(XLOOKUP(Players!$F10, Scoring!$A:$A, Scoring!$B:$B,"",1)) * (XLOOKUP(S$2, Weightings!$C$2:$C$36, Weightings!$I$2:$I$36,"",1))} -> 0.52 | T11: {=(XLOOKUP(Players!$F10, Scoring!$A:$A, Scoring!$B:$B,"",1)) * (XLOOKUP(T$2, Weightings!$C$2:$C$36, Weightings!$I$2:$I$36,"",1))} -> 2.08 | U11: {=(XLOOKUP(Players!$F10, Scoring!$A:$A, Scoring!$B:$B,"",1)) * (XLOOKUP(U$2, Weightings!$C$2:$C$36, Weightings!$I$2:$I$36,"",1))} -> 1.04 | V11: {=(XLOOKUP(Players!$G10, Scoring!$A:$A, Scoring!$B:$B,"",1)) * (XLOOKUP(V$2, Weightings!$C$2:$C$36, Weightings!$I$2:$I$36,"",1))} -> 1.75 | W11: {=(XLOOKUP(Players!$G10, Scoring!$A:$A, Scoring!$B:$B,"",1)) * (XLOOKUP(W$2, Weightings!$C$2:$C$36, Weightings!$I$2:$I$36,"",1))} -> 1.05 | X11: {=(XLOOKUP(Players!$G10, Scoring!$A:$A, Scoring!$B:$B,"",1)) * (XLOOKUP(X$2, Weightings!$C$2:$C$36, Weightings!$I$2:$I$36,"",1))} -> 1.75 | Y11: {=(XLOOKUP(Players!$G10, Scoring!$A:$A, Scoring!$B:$B,"",1)) * (XLOOKUP(Y$2, Weightings!$C$2:$C$36, Weightings!$I$2:$I$36,"",1))} -> 1.4 | Z11: {=(XLOOKUP(Players!$G10, Scoring!$A:$A, Scoring!$B:$B,"",1)) * (XLOOKUP(Z$2, Weightings!$C$2:$C$36, Weightings!$I$2:$I$36,"",1))} -> 1.05 | AA11: {=(XLOOKUP(Players!$G10, Scoring!$A:$A, Scoring!$B:$B,"",1)) * (XLOOKUP(AA$2, Weightings!$C$2:$C$36, Weightings!$I$2:$I$36,"",1))} -> 1.75 | AB11: {=(XLOOKUP(Players!$H10, Scoring!$A:$A, Scoring!$B:$B,"",1)) * (XLOOKUP(AB$2, Weightings!$C$2:$C$36, Weightings!$I$2:$I$36,"",1))} -> 1.56 | AC11: {=(XLOOKUP(Players!$H10, Scoring!$A:$A, Scoring!$B:$B,"",1)) * (XLOOKUP(AC$2, Weightings!$C$2:$C$36, Weightings!$I$2:$I$36,"",1))} -> 2.6 | AD11: {=(XLOOKUP(Players!$I10, Scoring!$A:$A, Scoring!$B:$B,"",1)) * (XLOOKUP(AD$2, Weightings!$C$2:$C$36, Weightings!$I$2:$I$36,"",1))} -> 2.08 | AE11: {=(XLOOKUP(Players!$I10, Scoring!$A:$A, Scoring!$B:$B,"",1)) * (XLOOKUP(AE$2, Weightings!$C$2:$C$36, Weightings!$I$2:$I$36,"",1))} -> 3.64 | AF11: {=(XLOOKUP(Players!$I10, Scoring!$A:$A, Scoring!$B:$B,"",1)) * (XLOOKUP(AF$2, Weightings!$C$2:$C$36, Weightings!$I$2:$I$36,"",1))} -> 1.56 | AG11: {=(XLOOKUP(Players!$I10, Scoring!$A:$A, Scoring!$B:$B,"",1)) * (XLOOKUP(AG$2, Weightings!$C$2:$C$36, Weightings!$I$2:$I$36,"",1))} -> 1.56 | AH11: {=(XLOOKUP(Players!$J10, Scoring!$A:$A, Scoring!$B:$B,"",1)) * (XLOOKUP(AH$2, Weightings!$C$2:$C$36, Weightings!$I$2:$I$36,"",1))} -> 1.4 | AI11: {=(XLOOKUP(Players!$J10, Scoring!$A:$A, Scoring!$B:$B,"",1)) * (XLOOKUP(AI$2, Weightings!$C$2:$C$36, Weightings!$I$2:$I$36,"",1))} -> 1.4 | AJ11: {=(XLOOKUP(Players!$J10, Scoring!$A:$A, Scoring!$B:$B,"",1)) * (XLOOKUP(AJ$2, Weightings!$C$2:$C$36, Weightings!$I$2:$I$36,"",1))} -> 0.35 | AK11: =SUM(A11:AJ11) -> 45.71
